[2024-11-12T21:46:41.389+0000] {local_task_job_runner.py:120} INFO - ::group::Pre task execution logs
[2024-11-12T21:46:41.428+0000] {taskinstance.py:2073} INFO - Dependencies all met for dep_context=non-requeueable deps ti=<TaskInstance: extractAPItoBronze.api_available manual__2024-11-12T21:23:43.667318+00:00 [queued]>
[2024-11-12T21:46:41.446+0000] {taskinstance.py:2073} INFO - Dependencies all met for dep_context=requeueable deps ti=<TaskInstance: extractAPItoBronze.api_available manual__2024-11-12T21:23:43.667318+00:00 [queued]>
[2024-11-12T21:46:41.448+0000] {taskinstance.py:2303} INFO - Starting attempt 16 of 19
[2024-11-12T21:46:41.484+0000] {taskinstance.py:2327} INFO - Executing <Task(HttpSensor): api_available> on 2024-11-12 21:23:43.667318+00:00
[2024-11-12T21:46:41.506+0000] {warnings.py:110} WARNING - /home/***/.local/lib/python3.12/site-packages/***/task/task_runner/standard_task_runner.py:61: DeprecationWarning: This process (pid=71) is multi-threaded, use of fork() may lead to deadlocks in the child.
  pid = os.fork()

[2024-11-12T21:46:41.511+0000] {standard_task_runner.py:63} INFO - Started process 73 to run task
[2024-11-12T21:46:41.511+0000] {standard_task_runner.py:90} INFO - Running: ['***', 'tasks', 'run', 'extractAPItoBronze', 'api_available', 'manual__2024-11-12T21:23:43.667318+00:00', '--job-id', '123', '--raw', '--subdir', 'DAGS_FOLDER/ExtracttoBronze.py', '--cfg-path', '/tmp/tmp0a_2xxu_']
[2024-11-12T21:46:41.518+0000] {standard_task_runner.py:91} INFO - Job 123: Subtask api_available
[2024-11-12T21:46:41.638+0000] {task_command.py:426} INFO - Running <TaskInstance: extractAPItoBronze.api_available manual__2024-11-12T21:23:43.667318+00:00 [running]> on host bbd2fa8da241
[2024-11-12T21:46:42.069+0000] {taskinstance.py:2644} INFO - Exporting env vars: AIRFLOW_CTX_DAG_OWNER='***' AIRFLOW_CTX_DAG_ID='extractAPItoBronze' AIRFLOW_CTX_TASK_ID='api_available' AIRFLOW_CTX_EXECUTION_DATE='2024-11-12T21:23:43.667318+00:00' AIRFLOW_CTX_TRY_NUMBER='16' AIRFLOW_CTX_DAG_RUN_ID='manual__2024-11-12T21:23:43.667318+00:00'
[2024-11-12T21:46:42.072+0000] {taskinstance.py:430} INFO - ::endgroup::
[2024-11-12T21:46:42.193+0000] {baseoperator.py:399} WARNING - HttpSensor.execute cannot be called outside TaskInstance!
[2024-11-12T21:46:42.195+0000] {http.py:137} INFO - Poking: breweries
[2024-11-12T21:46:42.220+0000] {base.py:84} INFO - Using connection ID 'api' for task execution.
[2024-11-12T21:46:44.341+0000] {http.py:199} ERROR - HTTP error: Not Found
[2024-11-12T21:46:44.343+0000] {http.py:200} ERROR - {"message":"Couldn't find Brewery"}
[2024-11-12T21:47:44.355+0000] {http.py:137} INFO - Poking: breweries
[2024-11-12T21:47:44.518+0000] {base.py:84} INFO - Using connection ID 'api' for task execution.
[2024-11-12T21:47:46.778+0000] {http.py:199} ERROR - HTTP error: Not Found
[2024-11-12T21:47:46.782+0000] {http.py:200} ERROR - {"message":"Couldn't find Brewery"}
[2024-11-12T21:48:46.794+0000] {http.py:137} INFO - Poking: breweries
[2024-11-12T21:48:46.837+0000] {base.py:84} INFO - Using connection ID 'api' for task execution.
[2024-11-12T21:48:48.773+0000] {http.py:199} ERROR - HTTP error: Not Found
[2024-11-12T21:48:48.776+0000] {http.py:200} ERROR - {"message":"Couldn't find Brewery"}
[2024-11-12T21:49:48.777+0000] {http.py:137} INFO - Poking: breweries
[2024-11-12T21:49:48.976+0000] {base.py:84} INFO - Using connection ID 'api' for task execution.
[2024-11-12T21:49:51.296+0000] {http.py:199} ERROR - HTTP error: Not Found
[2024-11-12T21:49:51.300+0000] {http.py:200} ERROR - {"message":"Couldn't find Brewery"}
[2024-11-12T21:50:39.177+0000] {local_task_job_runner.py:310} WARNING - State of this instance has been externally set to restarting. Terminating instance.
[2024-11-12T21:50:39.327+0000] {local_task_job_runner.py:222} INFO - ::endgroup::
[2024-11-12T21:50:39.371+0000] {process_utils.py:132} INFO - Sending 15 to group 73. PIDs of all processes in the group: [73]
[2024-11-12T21:50:39.376+0000] {process_utils.py:87} INFO - Sending the signal 15 to group 73
[2024-11-12T21:50:39.383+0000] {taskinstance.py:2607} ERROR - Received SIGTERM. Terminating subprocesses.
[2024-11-12T21:50:39.394+0000] {taskinstance.py:441} INFO - ::group::Post task execution logs
[2024-11-12T21:50:39.609+0000] {taskinstance.py:2890} ERROR - Task failed with exception
Traceback (most recent call last):
  File "/home/airflow/.local/lib/python3.12/site-packages/airflow/models/taskinstance.py", line 465, in _execute_task
    result = _execute_callable(context=context, **execute_callable_kwargs)
             ^^^^^^^^^^^^^^^^^^^^^^^^^^^^^^^^^^^^^^^^^^^^^^^^^^^^^^^^^^^^^
  File "/home/airflow/.local/lib/python3.12/site-packages/airflow/models/taskinstance.py", line 432, in _execute_callable
    return execute_callable(context=context, **execute_callable_kwargs)
           ^^^^^^^^^^^^^^^^^^^^^^^^^^^^^^^^^^^^^^^^^^^^^^^^^^^^^^^^^^^^
  File "/home/airflow/.local/lib/python3.12/site-packages/airflow/models/baseoperator.py", line 400, in wrapper
    return func(self, *args, **kwargs)
           ^^^^^^^^^^^^^^^^^^^^^^^^^^^
  File "/home/airflow/.local/lib/python3.12/site-packages/airflow/providers/http/sensors/http.py", line 164, in execute
    super().execute(context=context)
  File "/home/airflow/.local/lib/python3.12/site-packages/airflow/models/baseoperator.py", line 400, in wrapper
    return func(self, *args, **kwargs)
           ^^^^^^^^^^^^^^^^^^^^^^^^^^^
  File "/home/airflow/.local/lib/python3.12/site-packages/airflow/sensors/base.py", line 292, in execute
    time.sleep(self._get_next_poke_interval(started_at, run_duration, try_number))
  File "/home/airflow/.local/lib/python3.12/site-packages/airflow/models/taskinstance.py", line 2609, in signal_handler
    raise AirflowTaskTerminated("Task received SIGTERM signal")
airflow.exceptions.AirflowTaskTerminated: Task received SIGTERM signal
[2024-11-12T21:50:39.799+0000] {taskinstance.py:1205} INFO - Marking task as UP_FOR_RETRY. dag_id=extractAPItoBronze, task_id=api_available, execution_date=20241112T212343, start_date=20241112T214641, end_date=20241112T215039
[2024-11-12T21:50:40.157+0000] {process_utils.py:80} INFO - Process psutil.Process(pid=73, status='terminated', exitcode=2, started='21:46:41') (73) terminated with exit code 2
