[2024-11-12T22:37:09.644+0000] {task_context_logger.py:104} ERROR - Executor reports task instance <TaskInstance: extractAPItoBronze.get_api manual__2024-11-12T21:23:43.667318+00:00 [queued]> finished (failed) although the task says it's queued. (Info: None) Was the task killed externally?
