[2024-11-12T22:20:00.442+0000] {local_task_job_runner.py:120} INFO - ::group::Pre task execution logs
[2024-11-12T22:20:00.473+0000] {taskinstance.py:2073} INFO - Dependencies all met for dep_context=non-requeueable deps ti=<TaskInstance: extractAPItoBronze.get_api manual__2024-11-12T21:23:43.667318+00:00 [queued]>
[2024-11-12T22:20:00.489+0000] {taskinstance.py:2073} INFO - Dependencies all met for dep_context=requeueable deps ti=<TaskInstance: extractAPItoBronze.get_api manual__2024-11-12T21:23:43.667318+00:00 [queued]>
[2024-11-12T22:20:00.491+0000] {taskinstance.py:2303} INFO - Starting attempt 12 of 12
[2024-11-12T22:20:00.509+0000] {taskinstance.py:2327} INFO - Executing <Task(PythonOperator): get_api> on 2024-11-12 21:23:43.667318+00:00
[2024-11-12T22:20:00.520+0000] {warnings.py:110} WARNING - /home/***/.local/lib/python3.12/site-packages/***/task/task_runner/standard_task_runner.py:61: DeprecationWarning: This process (pid=489) is multi-threaded, use of fork() may lead to deadlocks in the child.
  pid = os.fork()

[2024-11-12T22:20:00.522+0000] {standard_task_runner.py:63} INFO - Started process 491 to run task
[2024-11-12T22:20:00.522+0000] {standard_task_runner.py:90} INFO - Running: ['***', 'tasks', 'run', 'extractAPItoBronze', 'get_api', 'manual__2024-11-12T21:23:43.667318+00:00', '--job-id', '138', '--raw', '--subdir', 'DAGS_FOLDER/ExtracttoBronze.py', '--cfg-path', '/tmp/tmp9j9as8u9']
[2024-11-12T22:20:00.526+0000] {standard_task_runner.py:91} INFO - Job 138: Subtask get_api
[2024-11-12T22:20:00.593+0000] {task_command.py:426} INFO - Running <TaskInstance: extractAPItoBronze.get_api manual__2024-11-12T21:23:43.667318+00:00 [running]> on host bbd2fa8da241
[2024-11-12T22:20:00.720+0000] {taskinstance.py:2644} INFO - Exporting env vars: AIRFLOW_CTX_DAG_OWNER='***' AIRFLOW_CTX_DAG_ID='extractAPItoBronze' AIRFLOW_CTX_TASK_ID='get_api' AIRFLOW_CTX_EXECUTION_DATE='2024-11-12T21:23:43.667318+00:00' AIRFLOW_CTX_TRY_NUMBER='12' AIRFLOW_CTX_DAG_RUN_ID='manual__2024-11-12T21:23:43.667318+00:00'
[2024-11-12T22:20:00.722+0000] {taskinstance.py:430} INFO - ::endgroup::
[2024-11-12T22:20:00.751+0000] {logging_mixin.py:188} INFO - https://api.openbrewerydb.org/breweries
[2024-11-12T22:20:19.698+0000] {taskinstance.py:441} INFO - ::group::Post task execution logs
[2024-11-12T22:20:19.700+0000] {taskinstance.py:2890} ERROR - Task failed with exception
Traceback (most recent call last):
  File "/home/airflow/.local/lib/python3.12/site-packages/airflow/models/taskinstance.py", line 465, in _execute_task
    result = _execute_callable(context=context, **execute_callable_kwargs)
             ^^^^^^^^^^^^^^^^^^^^^^^^^^^^^^^^^^^^^^^^^^^^^^^^^^^^^^^^^^^^^
  File "/home/airflow/.local/lib/python3.12/site-packages/airflow/models/taskinstance.py", line 432, in _execute_callable
    return execute_callable(context=context, **execute_callable_kwargs)
           ^^^^^^^^^^^^^^^^^^^^^^^^^^^^^^^^^^^^^^^^^^^^^^^^^^^^^^^^^^^^
  File "/home/airflow/.local/lib/python3.12/site-packages/airflow/models/baseoperator.py", line 400, in wrapper
    return func(self, *args, **kwargs)
           ^^^^^^^^^^^^^^^^^^^^^^^^^^^
  File "/home/airflow/.local/lib/python3.12/site-packages/airflow/operators/python.py", line 235, in execute
    return_value = self.execute_callable()
                   ^^^^^^^^^^^^^^^^^^^^^^^
  File "/home/airflow/.local/lib/python3.12/site-packages/airflow/operators/python.py", line 252, in execute_callable
    return self.python_callable(*self.op_args, **self.op_kwargs)
           ^^^^^^^^^^^^^^^^^^^^^^^^^^^^^^^^^^^^^^^^^^^^^^^^^^^^^
  File "/opt/airflow/dags/ExtracttoBronze.py", line 40, in processing_api_json
    if df.empty:
       ^^
NameError: name 'df' is not defined
[2024-11-12T22:20:19.720+0000] {taskinstance.py:1205} INFO - Marking task as FAILED. dag_id=extractAPItoBronze, task_id=get_api, execution_date=20241112T212343, start_date=20241112T222000, end_date=20241112T222019
[2024-11-12T22:20:19.722+0000] {logging_mixin.py:188} INFO - Unexpected error: [Errno 2] No such file or directory: '/Users/Bhrenner/Documents/Breweries-Case/dags/utils/password.txt'
[2024-11-12T22:20:19.723+0000] {logging_mixin.py:188} INFO - None
[2024-11-12T22:20:26.963+0000] {logging_mixin.py:188} INFO - Failed to send email: (535, b'5.7.139 Authentication unsuccessful, basic authentication is disabled. [CP3P284CA0141.BRAP284.PROD.OUTLOOK.COM 2024-11-12T22:20:25.421Z 08DD03009604F536]')
[2024-11-12T22:20:26.964+0000] {taskinstance.py:1182} ERROR - Error when executing email_status callback
Traceback (most recent call last):
  File "/home/airflow/.local/lib/python3.12/site-packages/airflow/models/taskinstance.py", line 2476, in _run_raw_task
    self._execute_task_with_callbacks(context, test_mode, session=session)
  File "/home/airflow/.local/lib/python3.12/site-packages/airflow/models/taskinstance.py", line 2663, in _execute_task_with_callbacks
    result = self._execute_task(context, task_orig)
             ^^^^^^^^^^^^^^^^^^^^^^^^^^^^^^^^^^^^^^
  File "/home/airflow/.local/lib/python3.12/site-packages/airflow/models/taskinstance.py", line 2686, in _execute_task
    return _execute_task(self, context, task_orig)
           ^^^^^^^^^^^^^^^^^^^^^^^^^^^^^^^^^^^^^^^
  File "/home/airflow/.local/lib/python3.12/site-packages/airflow/models/taskinstance.py", line 465, in _execute_task
    result = _execute_callable(context=context, **execute_callable_kwargs)
             ^^^^^^^^^^^^^^^^^^^^^^^^^^^^^^^^^^^^^^^^^^^^^^^^^^^^^^^^^^^^^
  File "/home/airflow/.local/lib/python3.12/site-packages/airflow/models/taskinstance.py", line 432, in _execute_callable
    return execute_callable(context=context, **execute_callable_kwargs)
           ^^^^^^^^^^^^^^^^^^^^^^^^^^^^^^^^^^^^^^^^^^^^^^^^^^^^^^^^^^^^
  File "/home/airflow/.local/lib/python3.12/site-packages/airflow/models/baseoperator.py", line 400, in wrapper
    return func(self, *args, **kwargs)
           ^^^^^^^^^^^^^^^^^^^^^^^^^^^
  File "/home/airflow/.local/lib/python3.12/site-packages/airflow/operators/python.py", line 235, in execute
    return_value = self.execute_callable()
                   ^^^^^^^^^^^^^^^^^^^^^^^
  File "/home/airflow/.local/lib/python3.12/site-packages/airflow/operators/python.py", line 252, in execute_callable
    return self.python_callable(*self.op_args, **self.op_kwargs)
           ^^^^^^^^^^^^^^^^^^^^^^^^^^^^^^^^^^^^^^^^^^^^^^^^^^^^^
  File "/opt/airflow/dags/ExtracttoBronze.py", line 40, in processing_api_json
    if df.empty:
       ^^
NameError: name 'df' is not defined

During handling of the above exception, another exception occurred:

Traceback (most recent call last):
  File "/opt/airflow/dags/utils/AdditionalFunctions.py", line 135, in email_status
    server.login('breweriescase@hotmail.com', password)
  File "/usr/local/lib/python3.12/smtplib.py", line 739, in login
    (code, resp) = self.auth(
                   ^^^^^^^^^^
  File "/usr/local/lib/python3.12/smtplib.py", line 652, in auth
    authobject(challenge).encode('ascii'), eol='')
    ^^^^^^^^^^^^^^^^^^^^^^^^^^^^
AttributeError: 'NoneType' object has no attribute 'encode'

During handling of the above exception, another exception occurred:

Traceback (most recent call last):
  File "/opt/airflow/dags/utils/AdditionalFunctions.py", line 130, in email_status
    with smtplib.SMTP('smtp-mail.outlook.com', 587) as server:
  File "/usr/local/lib/python3.12/smtplib.py", line 284, in __exit__
    raise SMTPResponseException(code, message)
smtplib.SMTPResponseException: (535, b'5.7.139 Authentication unsuccessful, basic authentication is disabled. [CP3P284CA0141.BRAP284.PROD.OUTLOOK.COM 2024-11-12T22:20:25.421Z 08DD03009604F536]')

During handling of the above exception, another exception occurred:

Traceback (most recent call last):
  File "/home/airflow/.local/lib/python3.12/site-packages/airflow/models/taskinstance.py", line 1179, in _run_finished_callback
    callback(context)
  File "/opt/airflow/dags/utils/AdditionalFunctions.py", line 144, in email_status
    airflow.utils.email.send_email(
    ^^^^^^^
NameError: name '***' is not defined
[2024-11-12T22:20:27.000+0000] {standard_task_runner.py:110} ERROR - Failed to execute job 138 for task get_api (name 'df' is not defined; 491)
[2024-11-12T22:20:27.025+0000] {local_task_job_runner.py:240} INFO - Task exited with return code 1
[2024-11-12T22:20:27.049+0000] {taskinstance.py:3482} INFO - 0 downstream tasks scheduled from follow-on schedule check
[2024-11-12T22:20:27.054+0000] {local_task_job_runner.py:222} INFO - ::endgroup::
