[2024-11-12T21:53:26.790+0000] {local_task_job_runner.py:120} INFO - ::group::Pre task execution logs
[2024-11-12T21:53:26.844+0000] {taskinstance.py:2073} INFO - Dependencies all met for dep_context=non-requeueable deps ti=<TaskInstance: extractAPItoBronze.get_api manual__2024-11-12T21:23:43.667318+00:00 [queued]>
[2024-11-12T21:53:26.869+0000] {taskinstance.py:2073} INFO - Dependencies all met for dep_context=requeueable deps ti=<TaskInstance: extractAPItoBronze.get_api manual__2024-11-12T21:23:43.667318+00:00 [queued]>
[2024-11-12T21:53:26.870+0000] {taskinstance.py:2303} INFO - Starting attempt 6 of 8
[2024-11-12T21:53:26.909+0000] {taskinstance.py:2327} INFO - Executing <Task(PythonOperator): get_api> on 2024-11-12 21:23:43.667318+00:00
[2024-11-12T21:53:26.926+0000] {warnings.py:110} WARNING - /home/***/.local/lib/python3.12/site-packages/***/task/task_runner/standard_task_runner.py:61: DeprecationWarning: This process (pid=158) is multi-threaded, use of fork() may lead to deadlocks in the child.
  pid = os.fork()

[2024-11-12T21:53:26.929+0000] {standard_task_runner.py:63} INFO - Started process 160 to run task
[2024-11-12T21:53:26.929+0000] {standard_task_runner.py:90} INFO - Running: ['***', 'tasks', 'run', 'extractAPItoBronze', 'get_api', 'manual__2024-11-12T21:23:43.667318+00:00', '--job-id', '130', '--raw', '--subdir', 'DAGS_FOLDER/ExtracttoBronze.py', '--cfg-path', '/tmp/tmpexlkk5ks']
[2024-11-12T21:53:26.936+0000] {standard_task_runner.py:91} INFO - Job 130: Subtask get_api
[2024-11-12T21:53:27.081+0000] {task_command.py:426} INFO - Running <TaskInstance: extractAPItoBronze.get_api manual__2024-11-12T21:23:43.667318+00:00 [running]> on host bbd2fa8da241
[2024-11-12T21:53:27.345+0000] {taskinstance.py:2644} INFO - Exporting env vars: AIRFLOW_CTX_DAG_OWNER='***' AIRFLOW_CTX_DAG_ID='extractAPItoBronze' AIRFLOW_CTX_TASK_ID='get_api' AIRFLOW_CTX_EXECUTION_DATE='2024-11-12T21:23:43.667318+00:00' AIRFLOW_CTX_TRY_NUMBER='6' AIRFLOW_CTX_DAG_RUN_ID='manual__2024-11-12T21:23:43.667318+00:00'
[2024-11-12T21:53:27.349+0000] {taskinstance.py:430} INFO - ::endgroup::
[2024-11-12T21:53:27.414+0000] {logging_mixin.py:188} INFO - https://api.openbrewerydb.org/breweries
[2024-11-12T21:53:27.928+0000] {taskinstance.py:441} INFO - ::group::Post task execution logs
[2024-11-12T21:53:27.930+0000] {taskinstance.py:2890} ERROR - Task failed with exception
Traceback (most recent call last):
  File "/home/airflow/.local/lib/python3.12/site-packages/airflow/models/taskinstance.py", line 465, in _execute_task
    result = _execute_callable(context=context, **execute_callable_kwargs)
             ^^^^^^^^^^^^^^^^^^^^^^^^^^^^^^^^^^^^^^^^^^^^^^^^^^^^^^^^^^^^^
  File "/home/airflow/.local/lib/python3.12/site-packages/airflow/models/taskinstance.py", line 432, in _execute_callable
    return execute_callable(context=context, **execute_callable_kwargs)
           ^^^^^^^^^^^^^^^^^^^^^^^^^^^^^^^^^^^^^^^^^^^^^^^^^^^^^^^^^^^^
  File "/home/airflow/.local/lib/python3.12/site-packages/airflow/models/baseoperator.py", line 400, in wrapper
    return func(self, *args, **kwargs)
           ^^^^^^^^^^^^^^^^^^^^^^^^^^^
  File "/home/airflow/.local/lib/python3.12/site-packages/airflow/operators/python.py", line 235, in execute
    return_value = self.execute_callable()
                   ^^^^^^^^^^^^^^^^^^^^^^^
  File "/home/airflow/.local/lib/python3.12/site-packages/airflow/operators/python.py", line 252, in execute_callable
    return self.python_callable(*self.op_args, **self.op_kwargs)
           ^^^^^^^^^^^^^^^^^^^^^^^^^^^^^^^^^^^^^^^^^^^^^^^^^^^^^
  File "/opt/airflow/dags/ExtracttoBronze.py", line 38, in processing_api_json
    df = get_api_content(api_endpoint)
         ^^^^^^^^^^^^^^^^^^^^^^^^^^^^^
  File "/opt/airflow/dags/ExtracttoBronze.py", line 28, in get_api_content
    breweriesDF = pd.concat([breweriesDF, pd.DataFrame(breweries)])
                             ^^^^^^^^^^^
UnboundLocalError: cannot access local variable 'breweriesDF' where it is not associated with a value
[2024-11-12T21:53:27.963+0000] {taskinstance.py:1205} INFO - Marking task as UP_FOR_RETRY. dag_id=extractAPItoBronze, task_id=get_api, execution_date=20241112T212343, start_date=20241112T215326, end_date=20241112T215327
[2024-11-12T21:53:27.964+0000] {logging_mixin.py:188} INFO - Unexpected error: [Errno 2] No such file or directory: '/Users/Bhrenner/Documents/Breweries-Case/dags/utils/password.txt'
[2024-11-12T21:53:27.965+0000] {logging_mixin.py:188} INFO - None
[2024-11-12T21:53:35.396+0000] {logging_mixin.py:188} INFO - Failed to send email: (535, b'5.7.139 Authentication unsuccessful, basic authentication is disabled. [CP5P284CA0167.BRAP284.PROD.OUTLOOK.COM 2024-11-12T21:53:33.840Z 08DD02E2B6815273]')
[2024-11-12T21:53:35.398+0000] {taskinstance.py:1182} ERROR - Error when executing email_status callback
Traceback (most recent call last):
  File "/home/airflow/.local/lib/python3.12/site-packages/airflow/models/taskinstance.py", line 2476, in _run_raw_task
    self._execute_task_with_callbacks(context, test_mode, session=session)
  File "/home/airflow/.local/lib/python3.12/site-packages/airflow/models/taskinstance.py", line 2663, in _execute_task_with_callbacks
    result = self._execute_task(context, task_orig)
             ^^^^^^^^^^^^^^^^^^^^^^^^^^^^^^^^^^^^^^
  File "/home/airflow/.local/lib/python3.12/site-packages/airflow/models/taskinstance.py", line 2686, in _execute_task
    return _execute_task(self, context, task_orig)
           ^^^^^^^^^^^^^^^^^^^^^^^^^^^^^^^^^^^^^^^
  File "/home/airflow/.local/lib/python3.12/site-packages/airflow/models/taskinstance.py", line 465, in _execute_task
    result = _execute_callable(context=context, **execute_callable_kwargs)
             ^^^^^^^^^^^^^^^^^^^^^^^^^^^^^^^^^^^^^^^^^^^^^^^^^^^^^^^^^^^^^
  File "/home/airflow/.local/lib/python3.12/site-packages/airflow/models/taskinstance.py", line 432, in _execute_callable
    return execute_callable(context=context, **execute_callable_kwargs)
           ^^^^^^^^^^^^^^^^^^^^^^^^^^^^^^^^^^^^^^^^^^^^^^^^^^^^^^^^^^^^
  File "/home/airflow/.local/lib/python3.12/site-packages/airflow/models/baseoperator.py", line 400, in wrapper
    return func(self, *args, **kwargs)
           ^^^^^^^^^^^^^^^^^^^^^^^^^^^
  File "/home/airflow/.local/lib/python3.12/site-packages/airflow/operators/python.py", line 235, in execute
    return_value = self.execute_callable()
                   ^^^^^^^^^^^^^^^^^^^^^^^
  File "/home/airflow/.local/lib/python3.12/site-packages/airflow/operators/python.py", line 252, in execute_callable
    return self.python_callable(*self.op_args, **self.op_kwargs)
           ^^^^^^^^^^^^^^^^^^^^^^^^^^^^^^^^^^^^^^^^^^^^^^^^^^^^^
  File "/opt/airflow/dags/ExtracttoBronze.py", line 38, in processing_api_json
    df = get_api_content(api_endpoint)
         ^^^^^^^^^^^^^^^^^^^^^^^^^^^^^
  File "/opt/airflow/dags/ExtracttoBronze.py", line 28, in get_api_content
    breweriesDF = pd.concat([breweriesDF, pd.DataFrame(breweries)])
                             ^^^^^^^^^^^
UnboundLocalError: cannot access local variable 'breweriesDF' where it is not associated with a value

During handling of the above exception, another exception occurred:

Traceback (most recent call last):
  File "/opt/airflow/dags/utils/AdditionalFunctions.py", line 121, in email_status
    server.login('breweriescase@hotmail.com', password)  # Login with the decrypted password
    ^^^^^^^^^^^^^^^^^^^^^^^^^^^^^^^^^^^^^^^^^^^^^^^^^^^
  File "/usr/local/lib/python3.12/smtplib.py", line 739, in login
    (code, resp) = self.auth(
                   ^^^^^^^^^^
  File "/usr/local/lib/python3.12/smtplib.py", line 652, in auth
    authobject(challenge).encode('ascii'), eol='')
    ^^^^^^^^^^^^^^^^^^^^^^^^^^^^
AttributeError: 'NoneType' object has no attribute 'encode'

During handling of the above exception, another exception occurred:

Traceback (most recent call last):
  File "/opt/airflow/dags/utils/AdditionalFunctions.py", line 117, in email_status
    with smtplib.SMTP('smtp-mail.outlook.com', 587) as server:
  File "/usr/local/lib/python3.12/smtplib.py", line 284, in __exit__
    raise SMTPResponseException(code, message)
smtplib.SMTPResponseException: (535, b'5.7.139 Authentication unsuccessful, basic authentication is disabled. [CP5P284CA0167.BRAP284.PROD.OUTLOOK.COM 2024-11-12T21:53:33.840Z 08DD02E2B6815273]')

During handling of the above exception, another exception occurred:

Traceback (most recent call last):
  File "/home/airflow/.local/lib/python3.12/site-packages/airflow/models/taskinstance.py", line 1179, in _run_finished_callback
    callback(context)
  File "/opt/airflow/dags/utils/AdditionalFunctions.py", line 129, in email_status
    airflow.utils.email.send_email(
    ^^^^^^^
NameError: name '***' is not defined
[2024-11-12T21:53:35.477+0000] {standard_task_runner.py:110} ERROR - Failed to execute job 130 for task get_api (cannot access local variable 'breweriesDF' where it is not associated with a value; 160)
[2024-11-12T21:53:35.529+0000] {local_task_job_runner.py:240} INFO - Task exited with return code 1
[2024-11-12T21:53:35.590+0000] {taskinstance.py:3482} INFO - 0 downstream tasks scheduled from follow-on schedule check
[2024-11-12T21:53:35.607+0000] {local_task_job_runner.py:222} INFO - ::endgroup::
